Workbook

Sheet WhatsApp Data
A1: Date | B1: Day | C1: Total Messages | D1: My Messages | E1: Your Messages | F1: Started By | G1: Ended By | H1: Doc Sent | I1: Doc Received | J1: Voice Note Sent | K1: Voice Note Received | L1: Call Sent | M1: Call Sent (Answered) | N1: Call Received | O1: Call Received (Answered) | P1: Call Duration (min) | Q1: Messages Deleted (By Me) | R1: Messages Deleted (By You) | S1: My Reactions | T1: Your Reactions | U1: My Stickers | V1: Your Stickers | W1: My Emojis | X1: Your Emojis | Y1: Links Sent | Z1: Links Received | AA1: Media Sent | AB1: Media Received
A2: 46041 | B2: =TEXT(A2,"ddd") -> Mon | C2: 12 | D2: 9 | E2: 3 | F2: Me | G2: Me | I2: 1
A3: 46042 | B3: =TEXT(A3,"ddd") -> Tue
A4: 46043 | B4: =TEXT(A4,"ddd") -> Wed
A5: 46044 | B5: =TEXT(A5,"ddd") -> Thu | C5: 4 | D5: 3 | E5: 1 | F5: Me | G5: Me | J5: 1
A6: 46045 | B6: =TEXT(A6,"ddd") -> Fri
A7: 46046 | B7: =TEXT(A7,"ddd") -> Sat
A8: 46047 | B8: =TEXT(A8,"ddd") -> Sun | C8: 2 | D8: 2 | F8: Me | G8: Me | AA8: 1
A9: 46048 | B9: =TEXT(A9,"ddd") -> Mon | C9: 24 | D9: 14 | E9: 10 | F9: Me | G9: You
A10: 46049 | B10: =TEXT(A10,"ddd") -> Tue
A11: 46050 | B11: =TEXT(A11,"ddd") -> Wed
A12: 46051 | B12: =TEXT(A12,"ddd") -> Thu
A13: 46052 | B13: =TEXT(A13,"ddd") -> Fri
A14: 46053 | B14: =TEXT(A14,"ddd") -> Sat
A15: 46054 | B15: =TEXT(A15,"ddd") -> Sun
A16: 46055 | B16: =TEXT(A16,"ddd") -> Mon
A17: 46056 | B17: =TEXT(A17,"ddd") -> Tue | C17: 2 | D17: 2 | F17: Me | G17: Me | H17: 1
A18: 46057 | B18: =TEXT(A18,"ddd") -> Wed
A19: 46058 | B19: =TEXT(A19,"ddd") -> Thu | C19: 15 | D19: 13 | E19: 2 | F19: Me | G19: Me | K19: 2
A20: 46059 | B20: =TEXT(A20,"ddd") -> Fri
A21: 46060 | B21: =TEXT(A21,"ddd") -> Sat
A22: 46061 | B22: =TEXT(A22,"ddd") -> Sun
A23: 46062 | B23: =TEXT(A23,"ddd") -> Mon | C23: 2 | D23: 1 | E23: 1 | F23: Me | G23: You | I23: 1
A24: 46063 | B24: =TEXT(A24,"ddd") -> Tue
A25: 46064 | B25: =TEXT(A25,"ddd") -> Wed
A26: 46065 | B26: =TEXT(A26,"ddd") -> Thu
A27: 46066 | B27: =TEXT(A27,"ddd") -> Fri | C27: 8 | D27: 4 | E27: 4 | F27: You | G27: You | I27: 4 | Z27: 1
A28: 46067 | B28: =TEXT(A28,"ddd") -> Sat
A29: 46068 | B29: =TEXT(A29,"ddd") -> Sun | C29: 2 | D29: 1 | E29: 1 | F29: Me | G29: You | J29: 1 | K29: 1
A30: 46069 | B30: =TEXT(A30,"ddd") -> Mon | C30: 35 | D30: 20 | E30: 15 | F30: You | G30: You | J30: 4 | K30: 4
A31: 46070 | B31: =TEXT(A31,"ddd") -> Tue
A32: 46071 | B32: =TEXT(A32,"ddd") -> Wed
A33: 46072 | B33: =TEXT(A33,"ddd") -> Thu
A34: 46073 | B34: =TEXT(A34,"ddd") -> Fri
A35: 46074 | B35: =TEXT(A35,"ddd") -> Sat | C35: 7 | D35: 1 | E35: 6 | F35: You | G35: You | I35: 5
A36: 46075 | B36: =TEXT(A36,"ddd") -> Sun | C36: 21 | D36: 6 | E36: 15 | F36: Me | G36: Me | J36: 1 | N36: 1 | T36: 1 | Z36: 2
A37: 46076 | B37: =TEXT(A37,"ddd") -> Mon | C37: 5 | D37: 3 | E37: 2 | F37: Me | G37: You | J37: 1
A38: 46077 | B38: =TEXT(A38,"ddd") -> Tue
A39: 46078 | B39: =TEXT(A39,"ddd") -> Wed
A40: 46079 | B40: =TEXT(A40,"ddd") -> Thu | C40: 10 | D40: 6 | E40: 4 | F40: Me | G40: You | J40: 2 | K40: 2 | T40: 1
...

Sheet Summary
A1: Totals (auto-calculate from 'WhatsApp Data')
A2: Days covered | B2: =COUNT('WhatsApp Data'!A2:A111) -> 110
A3: Days with messages | B3: =COUNTIF('WhatsApp Data'!C2:C111,">0") -> 45
A4: Started by Me (days) | B4: =COUNTIF('WhatsApp Data'!F2:F111,"Me") -> 28
A5: Started by You (days) | B5: =COUNTIF('WhatsApp Data'!F2:F111,"You") -> 17
A6: Ended by Me (days) | B6: =COUNTIF('WhatsApp Data'!G2:G111,"Me") -> 22
A7: Ended by You (days) | B7: =COUNTIF('WhatsApp Data'!G2:G111,"You") -> 23
A9: Metric | B9: Total | C9: Daily Average
A10: Total Messages | B10: =SUM('WhatsApp Data'!C2:C111) -> 329 | C10: =IFERROR(B10/$B$2,0) -> 2.9909091
A11: My Messages | B11: =SUM('WhatsApp Data'!D2:D111) -> 180 | C11: =IFERROR(B11/$B$2,0) -> 1.6363636
A12: Your Messages | B12: =SUM('WhatsApp Data'!E2:E111) -> 149 | C12: =IFERROR(B12/$B$2,0) -> 1.3545455
A13: Doc Sent | B13: =SUM('WhatsApp Data'!H2:H111) -> 4 | C13: =IFERROR(B13/$B$2,0) -> 0.036363636
A14: Doc Received | B14: =SUM('WhatsApp Data'!I2:I111) -> 13 | C14: =IFERROR(B14/$B$2,0) -> 0.11818182
A15: Voice Note Sent | B15: =SUM('WhatsApp Data'!J2:J111) -> 31 | C15: =IFERROR(B15/$B$2,0) -> 0.28181818
A16: Voice Note Received | B16: =SUM('WhatsApp Data'!K2:K111) -> 24 | C16: =IFERROR(B16/$B$2,0) -> 0.21818182
A17: Call Sent | B17: =SUM('WhatsApp Data'!L2:L111) -> 0 | C17: =IFERROR(B17/$B$2,0) -> 0
A18: Call Sent (Answered) | B18: =SUM('WhatsApp Data'!M2:M111) -> 0 | C18: =IFERROR(B18/$B$2,0) -> 0
A19: Call Received | B19: =SUM('WhatsApp Data'!N2:N111) -> 1 | C19: =IFERROR(B19/$B$2,0) -> 0.0090909091
A20: Call Received (Answered) | B20: =SUM('WhatsApp Data'!O2:O111) -> 0 | C20: =IFERROR(B20/$B$2,0) -> 0
A21: Call Duration (min) | B21: =SUM('WhatsApp Data'!P2:P111) -> 0 | C21: =IFERROR(B21/$B$2,0) -> 0
A22: Messages Deleted (By Me) | B22: =SUM('WhatsApp Data'!Q2:Q111) -> 0 | C22: =IFERROR(B22/$B$2,0) -> 0
A23: Messages Deleted (By You) | B23: =SUM('WhatsApp Data'!R2:R111) -> 3 | C23: =IFERROR(B23/$B$2,0) -> 0.027272727
A24: My Reactions | B24: =SUM('WhatsApp Data'!S2:S111) -> 3 | C24: =IFERROR(B24/$B$2,0) -> 0.027272727
A25: Your Reactions | B25: =SUM('WhatsApp Data'!T2:T111) -> 3 | C25: =IFERROR(B25/$B$2,0) -> 0.027272727
A26: My Stickers | B26: =SUM('WhatsApp Data'!U2:U111) -> 0 | C26: =IFERROR(B26/$B$2,0) -> 0
A27: Your Stickers | B27: =SUM('WhatsApp Data'!V2:V111) -> 0 | C27: =IFERROR(B27/$B$2,0) -> 0
A28: My Emojis | B28: =SUM('WhatsApp Data'!W2:W111) -> 0 | C28: =IFERROR(B28/$B$2,0) -> 0
A29: Your Emojis | B29: =SUM('WhatsApp Data'!X2:X111) -> 0 | C29: =IFERROR(B29/$B$2,0) -> 0
A30: Links Sent | B30: =SUM('WhatsApp Data'!Y2:Y111) -> 0 | C30: =IFERROR(B30/$B$2,0) -> 0
A31: Links Received | B31: =SUM('WhatsApp Data'!Z2:Z111) -> 10 | C31: =IFERROR(B31/$B$2,0) -> 0.090909091
A32: Media Sent | B32: =SUM('WhatsApp Data'!AA2:AA111) -> 4 | C32: =IFERROR(B32/$B$2,0) -> 0.036363636
A33: Media Received | B33: =SUM('WhatsApp Data'!AB2:AB111) -> 0 | C33: =IFERROR(B33/$B$2,0) -> 0
